<?xml version="1.0" encoding="utf-8"?>
<!-- =================================================================================== -->
<!-- |    This document was autogenerated by xacro from /home/app/catkin_ws/src/strirus_gait_planning/physical_object/robot_description/xarco/strirus_gamma.xacro | -->
<!-- |    EDITING THIS FILE BY HAND IS NOT RECOMMENDED                                 | -->
<!-- =================================================================================== -->
<robot name="strirus_gamma">
  <!-- Import Rviz colors -->
  <material name="black">
    <color rgba="0.0 0.0 0.0 1.0"/>
  </material>
  <material name="blue">
    <color rgba="0.0 0.0 0.8 1.0"/>
  </material>
  <material name="green">
    <color rgba="0.0 0.8 0.0 1.0"/>
  </material>
  <material name="grey">
    <color rgba="0.2 0.2 0.2 1.0"/>
  </material>
  <material name="orange">
    <color rgba="1.0 0.423529411765 0.0392156862745 1.0"/>
  </material>
  <material name="brown">
    <color rgba="0.870588235294 0.811764705882 0.764705882353 1.0"/>
  </material>
  <material name="red">
    <color rgba="0.8 0.0 0.0 1.0"/>
  </material>
  <material name="white">
    <color rgba="1.0 1.0 1.0 1.0"/>
  </material>
  <!-- Body description -->
  <link name="base_footprint"/>
  <joint name="base_footprint_body_1_part_fixed" type="fixed">
    <parent link="base_footprint"/>
    <child link="body_1_part"/>
    <origin rpy="0  0  0" xyz="0 0 0.08"/>
  </joint>
  <!-- body 1 -->
  <link name="body_1_part">
    <inertial>
      <mass value="0.665"/>
      <origin rpy="0  0  0" xyz="0.101 0 -0.002"/>
      <inertia ixx="0.005" ixy="0" ixz="0.0001366" iyy="0.013" iyz="0" izz="0.017"/>
    </inertial>
    <collision>
      <origin rpy="0  0  0" xyz="0 0 0"/>
      <geometry>
        <mesh filename="package://robot_description/strirus_cad_design/stl/body_1_collision.stl" scale="1 1 1"/>
      </geometry>
    </collision>
    <visual>
      <origin rpy="0  0  0" xyz="0 0 0"/>
      <geometry>
        <mesh filename="package://robot_description/strirus_cad_design/stl/body_1_visual.stl" scale="1 1 1"/>
        <!-- <mesh filename="package://robot_description/strirus_cad_design/stl/body_1_collision.stl" scale="1 1 1"/> -->
      </geometry>
      <material name="white"/>
    </visual>
  </link>
  <!-- tof camera 1-->
  <link name="tof_camera_1"/>
  <joint name="body_1_part_tof_camera_1_fixed" type="fixed">
    <parent link="body_1_part"/>
    <child link="tof_camera_1"/>
    <origin rpy="0  0  3.14159265359" xyz="-0.0245 0 0"/>
  </joint>
  <!-- imu 1 -->
  <link name="imu_1"/>
  <joint name="body_1_part_imu_1_fixed" type="fixed">
    <parent link="body_1_part"/>
    <child link="imu_1"/>
    <origin rpy="0  0  0" xyz="0 0 0"/>
  </joint>
  <!-- body 2 -->
  <link name="body_2_part">
    <inertial>
      <mass value="0.665"/>
      <origin rpy="0  0  0" xyz="0.146 0 -0.002"/>
      <inertia ixx="0.005" ixy="1.656e-06" ixz="0.0002448" iyy="0.02" iyz="-2.631e-08" izz="0.024"/>
    </inertial>
    <collision>
      <origin rpy="0  0  0" xyz="0 0 0"/>
      <geometry>
        <mesh filename="package://robot_description/strirus_cad_design/stl/body_2_collision.stl" scale="1 1 1"/>
      </geometry>
    </collision>
    <visual>
      <origin rpy="0  0  0" xyz="0 0 0"/>
      <geometry>
        <mesh filename="package://robot_description/strirus_cad_design/stl/body_2_visual.stl" scale="1 1 1"/>
        <!-- <mesh filename="package://robot_description/strirus_cad_design/stl/body_2_collision.stl" scale="1 1 1"/> -->
      </geometry>
      <material name="white"/>
    </visual>
  </link>
  <!-- tof camera 2 -->
  <link name="tof_camera_2"/>
  <joint name="body_2_part_tof_camera_2_fixed" type="fixed">
    <parent link="body_2_part"/>
    <child link="tof_camera_2"/>
    <origin rpy="0  0  0" xyz="0.2715 0 0"/>
  </joint>
  <!-- imu 1 -->
  <link name="imu_2"/>
  <joint name="body_2_part_imu_2_fixed" type="fixed">
    <parent link="body_2_part"/>
    <child link="imu_2"/>
    <origin rpy="0  0  0" xyz="0.2226 0 0"/>
  </joint>
  <!-- bridge 1 -->
  <link name="bridge_1_part">
    <inertial>
      <mass value="0.147"/>
      <origin rpy="0  0  0" xyz="0.005 0 0"/>
      <inertia ixx="0.0003384" ixy="0" ixz="0" iyy="5.442e-05" iyz="0" izz="0.0003303"/>
    </inertial>
    <collision>
      <origin rpy="0  0  0" xyz="0 0 0"/>
      <geometry>
        <mesh filename="package://robot_description/strirus_cad_design/stl/bridge_1_collision.stl" scale="1 1 1"/>
      </geometry>
    </collision>
    <visual>
      <origin rpy="0  0  0" xyz="0 0 0"/>
      <geometry>
        <mesh filename="package://robot_description/strirus_cad_design/stl/bridge_1_visual.stl" scale="1 1 1"/>
        <!-- <mesh filename="package://robot_description/strirus_cad_design/stl/bridge_1_collision.stl" scale="1 1 1"/> -->
      </geometry>
      <material name="white"/>
    </visual>
  </link>
  <!-- bridge 2 -->
  <link name="bridge_2_part">
    <inertial>
      <mass value="0.147"/>
      <origin rpy="0  0  0" xyz="0.025 0 0"/>
      <inertia ixx="0.0003654" ixy="0" ixz="-1.872e-06" iyy="0.0001394" iyz="0" izz="0.0004423"/>
    </inertial>
    <collision>
      <origin rpy="0  0  0" xyz="0 0 0"/>
      <geometry>
        <mesh filename="package://robot_description/strirus_cad_design/stl/bridge_2_collision.stl" scale="1 1 1"/>
      </geometry>
    </collision>
    <visual>
      <origin rpy="0  0  0" xyz="0 0 0"/>
      <geometry>
        <mesh filename="package://robot_description/strirus_cad_design/stl/bridge_2_visual.stl" scale="1 1 1"/>
        <!-- <mesh filename="package://robot_description/strirus_cad_design/stl/bridge_2_collision.stl" scale="1 1 1"/> -->
      </geometry>
      <material name="orange"/>
    </visual>
  </link>
  <joint name="segment_up_revolute" type="revolute">
    <parent link="bridge_1_part"/>
    <child link="bridge_2_part"/>
    <origin rpy="0 -0.0 0" xyz="0.03 0 0"/>
    <axis xyz="0 -1  0"/>
    <limit effort="5" lower="-1.1344640138" upper="1.1344640138" velocity="0.00872664625997"/>
    <dynamics damping="0.1" friction="0.0"/>
  </joint>
  <joint name="segment_side_revolute" type="revolute">
    <parent link="body_1_part"/>
    <child link="bridge_1_part"/>
    <origin rpy="0 0 -0.0" xyz="0.247 0 0"/>
    <axis xyz="0 0  -1"/>
    <limit effort="5" lower="-0.261799387799" upper="0.261799387799" velocity="0.00872664625997"/>
    <dynamics damping="0.0" friction="0.2"/>
  </joint>
  <joint name="bridge_2_part_body_2_part_fixed" type="fixed">
    <parent link="bridge_2_part"/>
    <child link="body_2_part"/>
    <origin rpy="0 0 0" xyz="0.03 0 0"/>
  </joint>
  <!--===================== Link description =====================-->
  <link name="motor_box_left_5">
    <inertial>
      <mass value="0.286"/>
      <origin rpy="0  0  0" xyz="0.053 0.003 0"/>
      <inertia ixx="8.104e-05" ixy="8.747e-06" ixz="2.555e-07" iyy="0.001" iyz="0" izz="0.001"/>
    </inertial>
    <collision>
      <origin rpy="0  0  0" xyz="0 0 0"/>
      <geometry>
        <mesh filename="package://robot_description/strirus_cad_design/stl/motor_box_collision.stl" scale="1 1 1"/>
      </geometry>
    </collision>
    <visual>
      <origin rpy="0  0  0" xyz="0 0 0"/>
      <geometry>
        <mesh filename="package://robot_description/strirus_cad_design/stl/motor_box_visual.stl" scale="1 1 1"/>
      </geometry>
      <material name="white"/>
    </visual>
  </link>
  <link name="leg_left_5">
    <inertial>
      <mass value="0.051"/>
      <origin rpy="0  0  0" xyz="-0.013348671 0 0"/>
      <inertia ixx="0.000102" ixy="0" ixz="-2.817e-05" iyy="0.0001322" iyz="0" izz="3.167e-05"/>
    </inertial>
    <collision>
      <origin rpy="0  0  0" xyz="0 0 0"/>
      <geometry>
        <mesh filename="package://robot_description/strirus_cad_design/stl/leg_80_collision.stl" scale="1 1 1"/>
      </geometry>
    </collision>
    <visual>
      <origin rpy="0 0 0" xyz="0 0 0"/>
      <geometry>
        <mesh filename="package://robot_description/strirus_cad_design/stl/leg_80_visual.stl" scale="1 1 1"/>
      </geometry>
    </visual>
  </link>
  <joint name="motor_box_left_5_fixed_joint" type="fixed">
    <child link="motor_box_left_5"/>
    <parent link="body_2_part"/>
    <origin rpy="0       0        1.308996939" xyz="0.231 0.0701  0"/>
  </joint>
  <joint name="leg_left_5_revolute_joint" type="revolute">
    <parent link="motor_box_left_5"/>
    <child link="leg_left_5"/>
    <origin rpy="0 10.471975512 -1.57079632679" xyz="0.123 0 0"/>
    <!--=============== Joint properties ===============-->
    <axis xyz="0 1  0"/>
    <limit effort="300" lower="-1e+5" upper="1e+5" velocity="3.0"/>
    <dynamics damping="0.001" friction="0.0"/>
  </joint>
  <!--===================== Leg transmission description =====================-->
  <transmission name="leg_left_5_trans">
    <type>transmission_interface/SimpleTransmission</type>
    <joint name="leg_left_5_revolute_joint">
      <hardwareInterface>hardware_interface/PositionJointInterface</hardwareInterface>
      <!-- <hardwareInterface>hardware_interface/EffortJointInterface</hardwareInterface> -->
    </joint>
    <actuator name="leg_left_5_motor">
      <mechanicalReduction>1</mechanicalReduction>
    </actuator>
  </transmission>
  <gazebo reference="leg_left_5">

        </gazebo>
  <gazebo reference="leg_left_5">
    <mu1 value="100.0"/>
    <mu2 value="100.0"/>
    <material>Gazebo/Green</material>
  </gazebo>
  <!-- frameName seems not working data are given according to the world frame -->
  <gazebo reference="leg_left_5">
    <sensor name="leg_left_5_bumper" type="contact">
      <always_on>true</always_on>
      <update_rate>50</update_rate>
      <contact>
        <collision>leg_left_5_collision</collision>
      </contact>
      <plugin filename="libgazebo_ros_bumper.so" name="leg_left_5_bumper_controller">
        <bumperTopicName>leg_left_5_bumper</bumperTopicName>
        <frameName>world</frameName>
      </plugin>
    </sensor>
  </gazebo>
  <!--===================== Link description =====================-->
  <link name="motor_box_left_4">
    <inertial>
      <mass value="0.286"/>
      <origin rpy="0  0  0" xyz="0.053 0.003 0"/>
      <inertia ixx="8.104e-05" ixy="8.747e-06" ixz="2.555e-07" iyy="0.001" iyz="0" izz="0.001"/>
    </inertial>
    <collision>
      <origin rpy="0  0  0" xyz="0 0 0"/>
      <geometry>
        <mesh filename="package://robot_description/strirus_cad_design/stl/motor_box_collision.stl" scale="1 1 1"/>
      </geometry>
    </collision>
    <visual>
      <origin rpy="0  0  0" xyz="0 0 0"/>
      <geometry>
        <mesh filename="package://robot_description/strirus_cad_design/stl/motor_box_visual.stl" scale="1 1 1"/>
      </geometry>
      <material name="white"/>
    </visual>
  </link>
  <link name="leg_left_4">
    <inertial>
      <mass value="0.051"/>
      <origin rpy="0  0  0" xyz="-0.013348671 0 0"/>
      <inertia ixx="0.000102" ixy="0" ixz="-2.817e-05" iyy="0.0001322" iyz="0" izz="3.167e-05"/>
    </inertial>
    <collision>
      <origin rpy="0  0  0" xyz="0 0 0"/>
      <geometry>
        <mesh filename="package://robot_description/strirus_cad_design/stl/leg_80_collision.stl" scale="1 1 1"/>
      </geometry>
    </collision>
    <visual>
      <origin rpy="0 0 0" xyz="0 0 0"/>
      <geometry>
        <mesh filename="package://robot_description/strirus_cad_design/stl/leg_80_visual.stl" scale="1 1 1"/>
      </geometry>
    </visual>
  </link>
  <joint name="motor_box_left_4_fixed_joint" type="fixed">
    <child link="motor_box_left_4"/>
    <parent link="body_2_part"/>
    <origin rpy="0       0        1.308996939" xyz="0.125 0.0701  0"/>
  </joint>
  <joint name="leg_left_4_revolute_joint" type="revolute">
    <parent link="motor_box_left_4"/>
    <child link="leg_left_4"/>
    <origin rpy="0 8.37758040957 -1.57079632679" xyz="0.123 0 0"/>
    <!--=============== Joint properties ===============-->
    <axis xyz="0 1  0"/>
    <limit effort="300" lower="-1e+5" upper="1e+5" velocity="3.0"/>
    <dynamics damping="0.001" friction="0.0"/>
  </joint>
  <!--===================== Leg transmission description =====================-->
  <transmission name="leg_left_4_trans">
    <type>transmission_interface/SimpleTransmission</type>
    <joint name="leg_left_4_revolute_joint">
      <hardwareInterface>hardware_interface/PositionJointInterface</hardwareInterface>
      <!-- <hardwareInterface>hardware_interface/EffortJointInterface</hardwareInterface> -->
    </joint>
    <actuator name="leg_left_4_motor">
      <mechanicalReduction>1</mechanicalReduction>
    </actuator>
  </transmission>
  <gazebo reference="leg_left_4">

        </gazebo>
  <gazebo reference="leg_left_4">
    <mu1 value="100.0"/>
    <mu2 value="100.0"/>
    <material>Gazebo/Green</material>
  </gazebo>
  <!-- frameName seems not working data are given according to the world frame -->
  <gazebo reference="leg_left_4">
    <sensor name="leg_left_4_bumper" type="contact">
      <always_on>true</always_on>
      <update_rate>50</update_rate>
      <contact>
        <collision>leg_left_4_collision</collision>
      </contact>
      <plugin filename="libgazebo_ros_bumper.so" name="leg_left_4_bumper_controller">
        <bumperTopicName>leg_left_4_bumper</bumperTopicName>
        <frameName>world</frameName>
      </plugin>
    </sensor>
  </gazebo>
  <!--===================== Link description =====================-->
  <link name="motor_box_left_3">
    <inertial>
      <mass value="0.286"/>
      <origin rpy="0  0  0" xyz="0.053 0.003 0"/>
      <inertia ixx="8.104e-05" ixy="8.747e-06" ixz="2.555e-07" iyy="0.001" iyz="0" izz="0.001"/>
    </inertial>
    <collision>
      <origin rpy="0  0  0" xyz="0 0 0"/>
      <geometry>
        <mesh filename="package://robot_description/strirus_cad_design/stl/motor_box_collision.stl" scale="1 1 1"/>
      </geometry>
    </collision>
    <visual>
      <origin rpy="0  0  0" xyz="0 0 0"/>
      <geometry>
        <mesh filename="package://robot_description/strirus_cad_design/stl/motor_box_visual.stl" scale="1 1 1"/>
      </geometry>
      <material name="white"/>
    </visual>
  </link>
  <link name="leg_left_3">
    <inertial>
      <mass value="0.051"/>
      <origin rpy="0  0  0" xyz="-0.013348671 0 0"/>
      <inertia ixx="0.000102" ixy="0" ixz="-2.817e-05" iyy="0.0001322" iyz="0" izz="3.167e-05"/>
    </inertial>
    <collision>
      <origin rpy="0  0  0" xyz="0 0 0"/>
      <geometry>
        <mesh filename="package://robot_description/strirus_cad_design/stl/leg_80_collision.stl" scale="1 1 1"/>
      </geometry>
    </collision>
    <visual>
      <origin rpy="0 0 0" xyz="0 0 0"/>
      <geometry>
        <mesh filename="package://robot_description/strirus_cad_design/stl/leg_80_visual.stl" scale="1 1 1"/>
      </geometry>
    </visual>
  </link>
  <joint name="motor_box_left_3_fixed_joint" type="fixed">
    <child link="motor_box_left_3"/>
    <parent link="body_2_part"/>
    <origin rpy="0       0        1.308996939" xyz="0.019 0.0701  0"/>
  </joint>
  <joint name="leg_left_3_revolute_joint" type="revolute">
    <parent link="motor_box_left_3"/>
    <child link="leg_left_3"/>
    <origin rpy="0 6.28318530718 -1.57079632679" xyz="0.123 0 0"/>
    <!--=============== Joint properties ===============-->
    <axis xyz="0 1  0"/>
    <limit effort="300" lower="-1e+5" upper="1e+5" velocity="3.0"/>
    <dynamics damping="0.001" friction="0.0"/>
  </joint>
  <!--===================== Leg transmission description =====================-->
  <transmission name="leg_left_3_trans">
    <type>transmission_interface/SimpleTransmission</type>
    <joint name="leg_left_3_revolute_joint">
      <hardwareInterface>hardware_interface/PositionJointInterface</hardwareInterface>
      <!-- <hardwareInterface>hardware_interface/EffortJointInterface</hardwareInterface> -->
    </joint>
    <actuator name="leg_left_3_motor">
      <mechanicalReduction>1</mechanicalReduction>
    </actuator>
  </transmission>
  <gazebo reference="leg_left_3">

        </gazebo>
  <gazebo reference="leg_left_3">
    <mu1 value="100.0"/>
    <mu2 value="100.0"/>
    <material>Gazebo/Green</material>
  </gazebo>
  <!-- frameName seems not working data are given according to the world frame -->
  <gazebo reference="leg_left_3">
    <sensor name="leg_left_3_bumper" type="contact">
      <always_on>true</always_on>
      <update_rate>50</update_rate>
      <contact>
        <collision>leg_left_3_collision</collision>
      </contact>
      <plugin filename="libgazebo_ros_bumper.so" name="leg_left_3_bumper_controller">
        <bumperTopicName>leg_left_3_bumper</bumperTopicName>
        <frameName>world</frameName>
      </plugin>
    </sensor>
  </gazebo>
  <!--===================== Link description =====================-->
  <link name="motor_box_left_2">
    <inertial>
      <mass value="0.286"/>
      <origin rpy="0  0  0" xyz="0.053 0.003 0"/>
      <inertia ixx="8.104e-05" ixy="8.747e-06" ixz="2.555e-07" iyy="0.001" iyz="0" izz="0.001"/>
    </inertial>
    <collision>
      <origin rpy="0  0  0" xyz="0 0 0"/>
      <geometry>
        <mesh filename="package://robot_description/strirus_cad_design/stl/motor_box_collision.stl" scale="1 1 1"/>
      </geometry>
    </collision>
    <visual>
      <origin rpy="0  0  0" xyz="0 0 0"/>
      <geometry>
        <mesh filename="package://robot_description/strirus_cad_design/stl/motor_box_visual.stl" scale="1 1 1"/>
      </geometry>
      <material name="white"/>
    </visual>
  </link>
  <link name="leg_left_2">
    <inertial>
      <mass value="0.051"/>
      <origin rpy="0  0  0" xyz="-0.013348671 0 0"/>
      <inertia ixx="0.000102" ixy="0" ixz="-2.817e-05" iyy="0.0001322" iyz="0" izz="3.167e-05"/>
    </inertial>
    <collision>
      <origin rpy="0  0  0" xyz="0 0 0"/>
      <geometry>
        <mesh filename="package://robot_description/strirus_cad_design/stl/leg_80_collision.stl" scale="1 1 1"/>
      </geometry>
    </collision>
    <visual>
      <origin rpy="0 0 0" xyz="0 0 0"/>
      <geometry>
        <mesh filename="package://robot_description/strirus_cad_design/stl/leg_80_visual.stl" scale="1 1 1"/>
      </geometry>
    </visual>
  </link>
  <joint name="motor_box_left_2_fixed_joint" type="fixed">
    <child link="motor_box_left_2"/>
    <parent link="body_1_part"/>
    <origin rpy="0       0        1.83259571459" xyz="0.228 0.0701  0"/>
  </joint>
  <joint name="leg_left_2_revolute_joint" type="revolute">
    <parent link="motor_box_left_2"/>
    <child link="leg_left_2"/>
    <origin rpy="0 4.18879020479 -1.57079632679" xyz="0.123 0 0"/>
    <!--=============== Joint properties ===============-->
    <axis xyz="0 1  0"/>
    <limit effort="300" lower="-1e+5" upper="1e+5" velocity="3.0"/>
    <dynamics damping="0.001" friction="0.0"/>
  </joint>
  <!--===================== Leg transmission description =====================-->
  <transmission name="leg_left_2_trans">
    <type>transmission_interface/SimpleTransmission</type>
    <joint name="leg_left_2_revolute_joint">
      <hardwareInterface>hardware_interface/PositionJointInterface</hardwareInterface>
      <!-- <hardwareInterface>hardware_interface/EffortJointInterface</hardwareInterface> -->
    </joint>
    <actuator name="leg_left_2_motor">
      <mechanicalReduction>1</mechanicalReduction>
    </actuator>
  </transmission>
  <gazebo reference="leg_left_2">

        </gazebo>
  <gazebo reference="leg_left_2">
    <mu1 value="100.0"/>
    <mu2 value="100.0"/>
    <material>Gazebo/Green</material>
  </gazebo>
  <!-- frameName seems not working data are given according to the world frame -->
  <gazebo reference="leg_left_2">
    <sensor name="leg_left_2_bumper" type="contact">
      <always_on>true</always_on>
      <update_rate>50</update_rate>
      <contact>
        <collision>leg_left_2_collision</collision>
      </contact>
      <plugin filename="libgazebo_ros_bumper.so" name="leg_left_2_bumper_controller">
        <bumperTopicName>leg_left_2_bumper</bumperTopicName>
        <frameName>world</frameName>
      </plugin>
    </sensor>
  </gazebo>
  <!--===================== Link description =====================-->
  <link name="motor_box_left_1">
    <inertial>
      <mass value="0.286"/>
      <origin rpy="0  0  0" xyz="0.053 0.003 0"/>
      <inertia ixx="8.104e-05" ixy="8.747e-06" ixz="2.555e-07" iyy="0.001" iyz="0" izz="0.001"/>
    </inertial>
    <collision>
      <origin rpy="0  0  0" xyz="0 0 0"/>
      <geometry>
        <mesh filename="package://robot_description/strirus_cad_design/stl/motor_box_collision.stl" scale="1 1 1"/>
      </geometry>
    </collision>
    <visual>
      <origin rpy="0  0  0" xyz="0 0 0"/>
      <geometry>
        <mesh filename="package://robot_description/strirus_cad_design/stl/motor_box_visual.stl" scale="1 1 1"/>
      </geometry>
      <material name="white"/>
    </visual>
  </link>
  <link name="leg_left_1">
    <inertial>
      <mass value="0.051"/>
      <origin rpy="0  0  0" xyz="-0.013348671 0 0"/>
      <inertia ixx="0.000102" ixy="0" ixz="-2.817e-05" iyy="0.0001322" iyz="0" izz="3.167e-05"/>
    </inertial>
    <collision>
      <origin rpy="0  0  0" xyz="0 0 0"/>
      <geometry>
        <mesh filename="package://robot_description/strirus_cad_design/stl/leg_80_collision.stl" scale="1 1 1"/>
      </geometry>
    </collision>
    <visual>
      <origin rpy="0 0 0" xyz="0 0 0"/>
      <geometry>
        <mesh filename="package://robot_description/strirus_cad_design/stl/leg_80_visual.stl" scale="1 1 1"/>
      </geometry>
    </visual>
  </link>
  <joint name="motor_box_left_1_fixed_joint" type="fixed">
    <child link="motor_box_left_1"/>
    <parent link="body_1_part"/>
    <origin rpy="0       0        1.83259571459" xyz="0.122 0.0701  0"/>
  </joint>
  <joint name="leg_left_1_revolute_joint" type="revolute">
    <parent link="motor_box_left_1"/>
    <child link="leg_left_1"/>
    <origin rpy="0 2.09439510239 -1.57079632679" xyz="0.123 0 0"/>
    <!--=============== Joint properties ===============-->
    <axis xyz="0 1  0"/>
    <limit effort="300" lower="-1e+5" upper="1e+5" velocity="3.0"/>
    <dynamics damping="0.001" friction="0.0"/>
  </joint>
  <!--===================== Leg transmission description =====================-->
  <transmission name="leg_left_1_trans">
    <type>transmission_interface/SimpleTransmission</type>
    <joint name="leg_left_1_revolute_joint">
      <hardwareInterface>hardware_interface/PositionJointInterface</hardwareInterface>
      <!-- <hardwareInterface>hardware_interface/EffortJointInterface</hardwareInterface> -->
    </joint>
    <actuator name="leg_left_1_motor">
      <mechanicalReduction>1</mechanicalReduction>
    </actuator>
  </transmission>
  <gazebo reference="leg_left_1">

        </gazebo>
  <gazebo reference="leg_left_1">
    <mu1 value="100.0"/>
    <mu2 value="100.0"/>
    <material>Gazebo/Green</material>
  </gazebo>
  <!-- frameName seems not working data are given according to the world frame -->
  <gazebo reference="leg_left_1">
    <sensor name="leg_left_1_bumper" type="contact">
      <always_on>true</always_on>
      <update_rate>50</update_rate>
      <contact>
        <collision>leg_left_1_collision</collision>
      </contact>
      <plugin filename="libgazebo_ros_bumper.so" name="leg_left_1_bumper_controller">
        <bumperTopicName>leg_left_1_bumper</bumperTopicName>
        <frameName>world</frameName>
      </plugin>
    </sensor>
  </gazebo>
  <!--===================== Link description =====================-->
  <link name="motor_box_left_0">
    <inertial>
      <mass value="0.286"/>
      <origin rpy="0  0  0" xyz="0.053 0.003 0"/>
      <inertia ixx="8.104e-05" ixy="8.747e-06" ixz="2.555e-07" iyy="0.001" iyz="0" izz="0.001"/>
    </inertial>
    <collision>
      <origin rpy="0  0  0" xyz="0 0 0"/>
      <geometry>
        <mesh filename="package://robot_description/strirus_cad_design/stl/motor_box_collision.stl" scale="1 1 1"/>
      </geometry>
    </collision>
    <visual>
      <origin rpy="0  0  0" xyz="0 0 0"/>
      <geometry>
        <mesh filename="package://robot_description/strirus_cad_design/stl/motor_box_visual.stl" scale="1 1 1"/>
      </geometry>
      <material name="white"/>
    </visual>
  </link>
  <link name="leg_left_0">
    <inertial>
      <mass value="0.051"/>
      <origin rpy="0  0  0" xyz="-0.013348671 0 0"/>
      <inertia ixx="0.000102" ixy="0" ixz="-2.817e-05" iyy="0.0001322" iyz="0" izz="3.167e-05"/>
    </inertial>
    <collision>
      <origin rpy="0  0  0" xyz="0 0 0"/>
      <geometry>
        <mesh filename="package://robot_description/strirus_cad_design/stl/leg_80_collision.stl" scale="1 1 1"/>
      </geometry>
    </collision>
    <visual>
      <origin rpy="0 0 0" xyz="0 0 0"/>
      <geometry>
        <mesh filename="package://robot_description/strirus_cad_design/stl/leg_80_visual.stl" scale="1 1 1"/>
      </geometry>
    </visual>
  </link>
  <joint name="motor_box_left_0_fixed_joint" type="fixed">
    <child link="motor_box_left_0"/>
    <parent link="body_1_part"/>
    <origin rpy="0       0        1.83259571459" xyz="0.016 0.0701  0"/>
  </joint>
  <joint name="leg_left_0_revolute_joint" type="revolute">
    <parent link="motor_box_left_0"/>
    <child link="leg_left_0"/>
    <origin rpy="0 0.0 -1.57079632679" xyz="0.123 0 0"/>
    <!--=============== Joint properties ===============-->
    <axis xyz="0 1  0"/>
    <limit effort="300" lower="-1e+5" upper="1e+5" velocity="3.0"/>
    <dynamics damping="0.001" friction="0.0"/>
  </joint>
  <!--===================== Leg transmission description =====================-->
  <transmission name="leg_left_0_trans">
    <type>transmission_interface/SimpleTransmission</type>
    <joint name="leg_left_0_revolute_joint">
      <hardwareInterface>hardware_interface/PositionJointInterface</hardwareInterface>
      <!-- <hardwareInterface>hardware_interface/EffortJointInterface</hardwareInterface> -->
    </joint>
    <actuator name="leg_left_0_motor">
      <mechanicalReduction>1</mechanicalReduction>
    </actuator>
  </transmission>
  <gazebo reference="leg_left_0">

        </gazebo>
  <gazebo reference="leg_left_0">
    <mu1 value="100.0"/>
    <mu2 value="100.0"/>
    <material>Gazebo/Green</material>
  </gazebo>
  <!-- frameName seems not working data are given according to the world frame -->
  <gazebo reference="leg_left_0">
    <sensor name="leg_left_0_bumper" type="contact">
      <always_on>true</always_on>
      <update_rate>50</update_rate>
      <contact>
        <collision>leg_left_0_collision</collision>
      </contact>
      <plugin filename="libgazebo_ros_bumper.so" name="leg_left_0_bumper_controller">
        <bumperTopicName>leg_left_0_bumper</bumperTopicName>
        <frameName>world</frameName>
      </plugin>
    </sensor>
  </gazebo>
  <!--===================== Link description =====================-->
  <link name="motor_box_right_5">
    <inertial>
      <mass value="0.286"/>
      <origin rpy="0  0  0" xyz="0.053 0.003 0"/>
      <inertia ixx="8.104e-05" ixy="8.747e-06" ixz="2.555e-07" iyy="0.001" iyz="0" izz="0.001"/>
    </inertial>
    <collision>
      <origin rpy="0  0  0" xyz="0 0 0"/>
      <geometry>
        <mesh filename="package://robot_description/strirus_cad_design/stl/motor_box_collision.stl" scale="1 1 1"/>
      </geometry>
    </collision>
    <visual>
      <origin rpy="0  0  0" xyz="0 0 0"/>
      <geometry>
        <mesh filename="package://robot_description/strirus_cad_design/stl/motor_box_visual.stl" scale="1 1 1"/>
      </geometry>
      <material name="white"/>
    </visual>
  </link>
  <link name="leg_right_5">
    <inertial>
      <mass value="0.051"/>
      <origin rpy="0  0  0" xyz="-0.013348671 0 0"/>
      <inertia ixx="0.000102" ixy="0" ixz="-2.817e-05" iyy="0.0001322" iyz="0" izz="3.167e-05"/>
    </inertial>
    <collision>
      <origin rpy="0  0  0" xyz="0 0 0"/>
      <geometry>
        <mesh filename="package://robot_description/strirus_cad_design/stl/leg_80_collision.stl" scale="1 1 1"/>
      </geometry>
    </collision>
    <visual>
      <origin rpy="0 0 0" xyz="0 0 0"/>
      <geometry>
        <mesh filename="package://robot_description/strirus_cad_design/stl/leg_80_visual.stl" scale="1 1 1"/>
      </geometry>
    </visual>
  </link>
  <joint name="motor_box_right_5_fixed_joint" type="fixed">
    <child link="motor_box_right_5"/>
    <parent link="body_2_part"/>
    <origin rpy="0       0        -1.308996939" xyz="0.231 -0.0701  0"/>
  </joint>
  <joint name="leg_right_5_revolute_joint" type="revolute">
    <parent link="motor_box_right_5"/>
    <child link="leg_right_5"/>
    <origin rpy="0 10.471975512 1.57079632679" xyz="0.123 0 0"/>
    <!--=============== Joint properties ===============-->
    <axis xyz="0 1  0"/>
    <limit effort="300" lower="-1e+5" upper="1e+5" velocity="3.0"/>
    <dynamics damping="0.001" friction="0.0"/>
  </joint>
  <!--===================== Leg transmission description =====================-->
  <transmission name="leg_right_5_trans">
    <type>transmission_interface/SimpleTransmission</type>
    <joint name="leg_right_5_revolute_joint">
      <hardwareInterface>hardware_interface/PositionJointInterface</hardwareInterface>
      <!-- <hardwareInterface>hardware_interface/EffortJointInterface</hardwareInterface> -->
    </joint>
    <actuator name="leg_right_5_motor">
      <mechanicalReduction>1</mechanicalReduction>
    </actuator>
  </transmission>
  <gazebo reference="leg_right_5">

        </gazebo>
  <gazebo reference="leg_right_5">
    <mu1 value="100.0"/>
    <mu2 value="100.0"/>
    <material>Gazebo/Green</material>
  </gazebo>
  <!-- frameName seems not working data are given according to the world frame -->
  <gazebo reference="leg_right_5">
    <sensor name="leg_right_5_bumper" type="contact">
      <always_on>true</always_on>
      <update_rate>50</update_rate>
      <contact>
        <collision>leg_right_5_collision</collision>
      </contact>
      <plugin filename="libgazebo_ros_bumper.so" name="leg_right_5_bumper_controller">
        <bumperTopicName>leg_right_5_bumper</bumperTopicName>
        <frameName>world</frameName>
      </plugin>
    </sensor>
  </gazebo>
  <!--===================== Link description =====================-->
  <link name="motor_box_right_4">
    <inertial>
      <mass value="0.286"/>
      <origin rpy="0  0  0" xyz="0.053 0.003 0"/>
      <inertia ixx="8.104e-05" ixy="8.747e-06" ixz="2.555e-07" iyy="0.001" iyz="0" izz="0.001"/>
    </inertial>
    <collision>
      <origin rpy="0  0  0" xyz="0 0 0"/>
      <geometry>
        <mesh filename="package://robot_description/strirus_cad_design/stl/motor_box_collision.stl" scale="1 1 1"/>
      </geometry>
    </collision>
    <visual>
      <origin rpy="0  0  0" xyz="0 0 0"/>
      <geometry>
        <mesh filename="package://robot_description/strirus_cad_design/stl/motor_box_visual.stl" scale="1 1 1"/>
      </geometry>
      <material name="white"/>
    </visual>
  </link>
  <link name="leg_right_4">
    <inertial>
      <mass value="0.051"/>
      <origin rpy="0  0  0" xyz="-0.013348671 0 0"/>
      <inertia ixx="0.000102" ixy="0" ixz="-2.817e-05" iyy="0.0001322" iyz="0" izz="3.167e-05"/>
    </inertial>
    <collision>
      <origin rpy="0  0  0" xyz="0 0 0"/>
      <geometry>
        <mesh filename="package://robot_description/strirus_cad_design/stl/leg_80_collision.stl" scale="1 1 1"/>
      </geometry>
    </collision>
    <visual>
      <origin rpy="0 0 0" xyz="0 0 0"/>
      <geometry>
        <mesh filename="package://robot_description/strirus_cad_design/stl/leg_80_visual.stl" scale="1 1 1"/>
      </geometry>
    </visual>
  </link>
  <joint name="motor_box_right_4_fixed_joint" type="fixed">
    <child link="motor_box_right_4"/>
    <parent link="body_2_part"/>
    <origin rpy="0       0        -1.308996939" xyz="0.125 -0.0701  0"/>
  </joint>
  <joint name="leg_right_4_revolute_joint" type="revolute">
    <parent link="motor_box_right_4"/>
    <child link="leg_right_4"/>
    <origin rpy="0 8.37758040957 1.57079632679" xyz="0.123 0 0"/>
    <!--=============== Joint properties ===============-->
    <axis xyz="0 1  0"/>
    <limit effort="300" lower="-1e+5" upper="1e+5" velocity="3.0"/>
    <dynamics damping="0.001" friction="0.0"/>
  </joint>
  <!--===================== Leg transmission description =====================-->
  <transmission name="leg_right_4_trans">
    <type>transmission_interface/SimpleTransmission</type>
    <joint name="leg_right_4_revolute_joint">
      <hardwareInterface>hardware_interface/PositionJointInterface</hardwareInterface>
      <!-- <hardwareInterface>hardware_interface/EffortJointInterface</hardwareInterface> -->
    </joint>
    <actuator name="leg_right_4_motor">
      <mechanicalReduction>1</mechanicalReduction>
    </actuator>
  </transmission>
  <gazebo reference="leg_right_4">

        </gazebo>
  <gazebo reference="leg_right_4">
    <mu1 value="100.0"/>
    <mu2 value="100.0"/>
    <material>Gazebo/Green</material>
  </gazebo>
  <!-- frameName seems not working data are given according to the world frame -->
  <gazebo reference="leg_right_4">
    <sensor name="leg_right_4_bumper" type="contact">
      <always_on>true</always_on>
      <update_rate>50</update_rate>
      <contact>
        <collision>leg_right_4_collision</collision>
      </contact>
      <plugin filename="libgazebo_ros_bumper.so" name="leg_right_4_bumper_controller">
        <bumperTopicName>leg_right_4_bumper</bumperTopicName>
        <frameName>world</frameName>
      </plugin>
    </sensor>
  </gazebo>
  <!--===================== Link description =====================-->
  <link name="motor_box_right_3">
    <inertial>
      <mass value="0.286"/>
      <origin rpy="0  0  0" xyz="0.053 0.003 0"/>
      <inertia ixx="8.104e-05" ixy="8.747e-06" ixz="2.555e-07" iyy="0.001" iyz="0" izz="0.001"/>
    </inertial>
    <collision>
      <origin rpy="0  0  0" xyz="0 0 0"/>
      <geometry>
        <mesh filename="package://robot_description/strirus_cad_design/stl/motor_box_collision.stl" scale="1 1 1"/>
      </geometry>
    </collision>
    <visual>
      <origin rpy="0  0  0" xyz="0 0 0"/>
      <geometry>
        <mesh filename="package://robot_description/strirus_cad_design/stl/motor_box_visual.stl" scale="1 1 1"/>
      </geometry>
      <material name="white"/>
    </visual>
  </link>
  <link name="leg_right_3">
    <inertial>
      <mass value="0.051"/>
      <origin rpy="0  0  0" xyz="-0.013348671 0 0"/>
      <inertia ixx="0.000102" ixy="0" ixz="-2.817e-05" iyy="0.0001322" iyz="0" izz="3.167e-05"/>
    </inertial>
    <collision>
      <origin rpy="0  0  0" xyz="0 0 0"/>
      <geometry>
        <mesh filename="package://robot_description/strirus_cad_design/stl/leg_80_collision.stl" scale="1 1 1"/>
      </geometry>
    </collision>
    <visual>
      <origin rpy="0 0 0" xyz="0 0 0"/>
      <geometry>
        <mesh filename="package://robot_description/strirus_cad_design/stl/leg_80_visual.stl" scale="1 1 1"/>
      </geometry>
    </visual>
  </link>
  <joint name="motor_box_right_3_fixed_joint" type="fixed">
    <child link="motor_box_right_3"/>
    <parent link="body_2_part"/>
    <origin rpy="0       0        -1.308996939" xyz="0.019 -0.0701  0"/>
  </joint>
  <joint name="leg_right_3_revolute_joint" type="revolute">
    <parent link="motor_box_right_3"/>
    <child link="leg_right_3"/>
    <origin rpy="0 6.28318530718 1.57079632679" xyz="0.123 0 0"/>
    <!--=============== Joint properties ===============-->
    <axis xyz="0 1  0"/>
    <limit effort="300" lower="-1e+5" upper="1e+5" velocity="3.0"/>
    <dynamics damping="0.001" friction="0.0"/>
  </joint>
  <!--===================== Leg transmission description =====================-->
  <transmission name="leg_right_3_trans">
    <type>transmission_interface/SimpleTransmission</type>
    <joint name="leg_right_3_revolute_joint">
      <hardwareInterface>hardware_interface/PositionJointInterface</hardwareInterface>
      <!-- <hardwareInterface>hardware_interface/EffortJointInterface</hardwareInterface> -->
    </joint>
    <actuator name="leg_right_3_motor">
      <mechanicalReduction>1</mechanicalReduction>
    </actuator>
  </transmission>
  <gazebo reference="leg_right_3">

        </gazebo>
  <gazebo reference="leg_right_3">
    <mu1 value="100.0"/>
    <mu2 value="100.0"/>
    <material>Gazebo/Green</material>
  </gazebo>
  <!-- frameName seems not working data are given according to the world frame -->
  <gazebo reference="leg_right_3">
    <sensor name="leg_right_3_bumper" type="contact">
      <always_on>true</always_on>
      <update_rate>50</update_rate>
      <contact>
        <collision>leg_right_3_collision</collision>
      </contact>
      <plugin filename="libgazebo_ros_bumper.so" name="leg_right_3_bumper_controller">
        <bumperTopicName>leg_right_3_bumper</bumperTopicName>
        <frameName>world</frameName>
      </plugin>
    </sensor>
  </gazebo>
  <!--===================== Link description =====================-->
  <link name="motor_box_right_2">
    <inertial>
      <mass value="0.286"/>
      <origin rpy="0  0  0" xyz="0.053 0.003 0"/>
      <inertia ixx="8.104e-05" ixy="8.747e-06" ixz="2.555e-07" iyy="0.001" iyz="0" izz="0.001"/>
    </inertial>
    <collision>
      <origin rpy="0  0  0" xyz="0 0 0"/>
      <geometry>
        <mesh filename="package://robot_description/strirus_cad_design/stl/motor_box_collision.stl" scale="1 1 1"/>
      </geometry>
    </collision>
    <visual>
      <origin rpy="0  0  0" xyz="0 0 0"/>
      <geometry>
        <mesh filename="package://robot_description/strirus_cad_design/stl/motor_box_visual.stl" scale="1 1 1"/>
      </geometry>
      <material name="white"/>
    </visual>
  </link>
  <link name="leg_right_2">
    <inertial>
      <mass value="0.051"/>
      <origin rpy="0  0  0" xyz="-0.013348671 0 0"/>
      <inertia ixx="0.000102" ixy="0" ixz="-2.817e-05" iyy="0.0001322" iyz="0" izz="3.167e-05"/>
    </inertial>
    <collision>
      <origin rpy="0  0  0" xyz="0 0 0"/>
      <geometry>
        <mesh filename="package://robot_description/strirus_cad_design/stl/leg_80_collision.stl" scale="1 1 1"/>
      </geometry>
    </collision>
    <visual>
      <origin rpy="0 0 0" xyz="0 0 0"/>
      <geometry>
        <mesh filename="package://robot_description/strirus_cad_design/stl/leg_80_visual.stl" scale="1 1 1"/>
      </geometry>
    </visual>
  </link>
  <joint name="motor_box_right_2_fixed_joint" type="fixed">
    <child link="motor_box_right_2"/>
    <parent link="body_1_part"/>
    <origin rpy="0       0        -1.83259571459" xyz="0.228 -0.0701  0"/>
  </joint>
  <joint name="leg_right_2_revolute_joint" type="revolute">
    <parent link="motor_box_right_2"/>
    <child link="leg_right_2"/>
    <origin rpy="0 4.18879020479 1.57079632679" xyz="0.123 0 0"/>
    <!--=============== Joint properties ===============-->
    <axis xyz="0 1  0"/>
    <limit effort="300" lower="-1e+5" upper="1e+5" velocity="3.0"/>
    <dynamics damping="0.001" friction="0.0"/>
  </joint>
  <!--===================== Leg transmission description =====================-->
  <transmission name="leg_right_2_trans">
    <type>transmission_interface/SimpleTransmission</type>
    <joint name="leg_right_2_revolute_joint">
      <hardwareInterface>hardware_interface/PositionJointInterface</hardwareInterface>
      <!-- <hardwareInterface>hardware_interface/EffortJointInterface</hardwareInterface> -->
    </joint>
    <actuator name="leg_right_2_motor">
      <mechanicalReduction>1</mechanicalReduction>
    </actuator>
  </transmission>
  <gazebo reference="leg_right_2">

        </gazebo>
  <gazebo reference="leg_right_2">
    <mu1 value="100.0"/>
    <mu2 value="100.0"/>
    <material>Gazebo/Green</material>
  </gazebo>
  <!-- frameName seems not working data are given according to the world frame -->
  <gazebo reference="leg_right_2">
    <sensor name="leg_right_2_bumper" type="contact">
      <always_on>true</always_on>
      <update_rate>50</update_rate>
      <contact>
        <collision>leg_right_2_collision</collision>
      </contact>
      <plugin filename="libgazebo_ros_bumper.so" name="leg_right_2_bumper_controller">
        <bumperTopicName>leg_right_2_bumper</bumperTopicName>
        <frameName>world</frameName>
      </plugin>
    </sensor>
  </gazebo>
  <!--===================== Link description =====================-->
  <link name="motor_box_right_1">
    <inertial>
      <mass value="0.286"/>
      <origin rpy="0  0  0" xyz="0.053 0.003 0"/>
      <inertia ixx="8.104e-05" ixy="8.747e-06" ixz="2.555e-07" iyy="0.001" iyz="0" izz="0.001"/>
    </inertial>
    <collision>
      <origin rpy="0  0  0" xyz="0 0 0"/>
      <geometry>
        <mesh filename="package://robot_description/strirus_cad_design/stl/motor_box_collision.stl" scale="1 1 1"/>
      </geometry>
    </collision>
    <visual>
      <origin rpy="0  0  0" xyz="0 0 0"/>
      <geometry>
        <mesh filename="package://robot_description/strirus_cad_design/stl/motor_box_visual.stl" scale="1 1 1"/>
      </geometry>
      <material name="white"/>
    </visual>
  </link>
  <link name="leg_right_1">
    <inertial>
      <mass value="0.051"/>
      <origin rpy="0  0  0" xyz="-0.013348671 0 0"/>
      <inertia ixx="0.000102" ixy="0" ixz="-2.817e-05" iyy="0.0001322" iyz="0" izz="3.167e-05"/>
    </inertial>
    <collision>
      <origin rpy="0  0  0" xyz="0 0 0"/>
      <geometry>
        <mesh filename="package://robot_description/strirus_cad_design/stl/leg_80_collision.stl" scale="1 1 1"/>
      </geometry>
    </collision>
    <visual>
      <origin rpy="0 0 0" xyz="0 0 0"/>
      <geometry>
        <mesh filename="package://robot_description/strirus_cad_design/stl/leg_80_visual.stl" scale="1 1 1"/>
      </geometry>
    </visual>
  </link>
  <joint name="motor_box_right_1_fixed_joint" type="fixed">
    <child link="motor_box_right_1"/>
    <parent link="body_1_part"/>
    <origin rpy="0       0        -1.83259571459" xyz="0.122 -0.0701  0"/>
  </joint>
  <joint name="leg_right_1_revolute_joint" type="revolute">
    <parent link="motor_box_right_1"/>
    <child link="leg_right_1"/>
    <origin rpy="0 2.09439510239 1.57079632679" xyz="0.123 0 0"/>
    <!--=============== Joint properties ===============-->
    <axis xyz="0 1  0"/>
    <limit effort="300" lower="-1e+5" upper="1e+5" velocity="3.0"/>
    <dynamics damping="0.001" friction="0.0"/>
  </joint>
  <!--===================== Leg transmission description =====================-->
  <transmission name="leg_right_1_trans">
    <type>transmission_interface/SimpleTransmission</type>
    <joint name="leg_right_1_revolute_joint">
      <hardwareInterface>hardware_interface/PositionJointInterface</hardwareInterface>
      <!-- <hardwareInterface>hardware_interface/EffortJointInterface</hardwareInterface> -->
    </joint>
    <actuator name="leg_right_1_motor">
      <mechanicalReduction>1</mechanicalReduction>
    </actuator>
  </transmission>
  <gazebo reference="leg_right_1">

        </gazebo>
  <gazebo reference="leg_right_1">
    <mu1 value="100.0"/>
    <mu2 value="100.0"/>
    <material>Gazebo/Green</material>
  </gazebo>
  <!-- frameName seems not working data are given according to the world frame -->
  <gazebo reference="leg_right_1">
    <sensor name="leg_right_1_bumper" type="contact">
      <always_on>true</always_on>
      <update_rate>50</update_rate>
      <contact>
        <collision>leg_right_1_collision</collision>
      </contact>
      <plugin filename="libgazebo_ros_bumper.so" name="leg_right_1_bumper_controller">
        <bumperTopicName>leg_right_1_bumper</bumperTopicName>
        <frameName>world</frameName>
      </plugin>
    </sensor>
  </gazebo>
  <!--===================== Link description =====================-->
  <link name="motor_box_right_0">
    <inertial>
      <mass value="0.286"/>
      <origin rpy="0  0  0" xyz="0.053 0.003 0"/>
      <inertia ixx="8.104e-05" ixy="8.747e-06" ixz="2.555e-07" iyy="0.001" iyz="0" izz="0.001"/>
    </inertial>
    <collision>
      <origin rpy="0  0  0" xyz="0 0 0"/>
      <geometry>
        <mesh filename="package://robot_description/strirus_cad_design/stl/motor_box_collision.stl" scale="1 1 1"/>
      </geometry>
    </collision>
    <visual>
      <origin rpy="0  0  0" xyz="0 0 0"/>
      <geometry>
        <mesh filename="package://robot_description/strirus_cad_design/stl/motor_box_visual.stl" scale="1 1 1"/>
      </geometry>
      <material name="white"/>
    </visual>
  </link>
  <link name="leg_right_0">
    <inertial>
      <mass value="0.051"/>
      <origin rpy="0  0  0" xyz="-0.013348671 0 0"/>
      <inertia ixx="0.000102" ixy="0" ixz="-2.817e-05" iyy="0.0001322" iyz="0" izz="3.167e-05"/>
    </inertial>
    <collision>
      <origin rpy="0  0  0" xyz="0 0 0"/>
      <geometry>
        <mesh filename="package://robot_description/strirus_cad_design/stl/leg_80_collision.stl" scale="1 1 1"/>
      </geometry>
    </collision>
    <visual>
      <origin rpy="0 0 0" xyz="0 0 0"/>
      <geometry>
        <mesh filename="package://robot_description/strirus_cad_design/stl/leg_80_visual.stl" scale="1 1 1"/>
      </geometry>
    </visual>
  </link>
  <joint name="motor_box_right_0_fixed_joint" type="fixed">
    <child link="motor_box_right_0"/>
    <parent link="body_1_part"/>
    <origin rpy="0       0        -1.83259571459" xyz="0.016 -0.0701  0"/>
  </joint>
  <joint name="leg_right_0_revolute_joint" type="revolute">
    <parent link="motor_box_right_0"/>
    <child link="leg_right_0"/>
    <origin rpy="0 0.0 1.57079632679" xyz="0.123 0 0"/>
    <!--=============== Joint properties ===============-->
    <axis xyz="0 1  0"/>
    <limit effort="300" lower="-1e+5" upper="1e+5" velocity="3.0"/>
    <dynamics damping="0.001" friction="0.0"/>
  </joint>
  <!--===================== Leg transmission description =====================-->
  <transmission name="leg_right_0_trans">
    <type>transmission_interface/SimpleTransmission</type>
    <joint name="leg_right_0_revolute_joint">
      <hardwareInterface>hardware_interface/PositionJointInterface</hardwareInterface>
      <!-- <hardwareInterface>hardware_interface/EffortJointInterface</hardwareInterface> -->
    </joint>
    <actuator name="leg_right_0_motor">
      <mechanicalReduction>1</mechanicalReduction>
    </actuator>
  </transmission>
  <gazebo reference="leg_right_0">

        </gazebo>
  <gazebo reference="leg_right_0">
    <mu1 value="100.0"/>
    <mu2 value="100.0"/>
    <material>Gazebo/Green</material>
  </gazebo>
  <!-- frameName seems not working data are given according to the world frame -->
  <gazebo reference="leg_right_0">
    <sensor name="leg_right_0_bumper" type="contact">
      <always_on>true</always_on>
      <update_rate>50</update_rate>
      <contact>
        <collision>leg_right_0_collision</collision>
      </contact>
      <plugin filename="libgazebo_ros_bumper.so" name="leg_right_0_bumper_controller">
        <bumperTopicName>leg_right_0_bumper</bumperTopicName>
        <frameName>world</frameName>
      </plugin>
    </sensor>
  </gazebo>
  <!--====================== Plugin TOF camera 2 ======================-->
  <gazebo reference="tof_camera_2">
    <sensor name="tof_camera_2_camera" type="depth">
      <update_rate>45</update_rate>
      <camera>
        <horizontal_fov>1.0821</horizontal_fov>
        <image>
          <width>224</width>
          <height>171</height>
          <format>L8</format>
        </image>
        <clip>
          <near>0.01</near>
          <far>4</far>
        </clip>
      </camera>
      <plugin filename="libgazebo_ros_openni_kinect.so" name="camera_2_plugin">
        <baseline>0.2</baseline>
        <alwaysOn>true</alwaysOn>
        <updateRate>0.0</updateRate>
        <cameraName>pico_flexx2</cameraName>
        <imageTopicName>/pico_flexx2/color/image_raw</imageTopicName>
        <cameraInfoTopicName>/pico_flexx2/camera_info</cameraInfoTopicName>
        <depthImageTopicName>/pico_flexx2/image_depth</depthImageTopicName>
        <depthImageCameraInfoTopicName>/pico_flexx2/camera_info</depthImageCameraInfoTopicName>
        <pointCloudTopicName>/pico_flexx/points2</pointCloudTopicName>
        <frameName>tof_camera_2</frameName>
        <pointCloudCutoff>0.5</pointCloudCutoff>
        <pointCloudCutoffMax>3.0</pointCloudCutoffMax>
        <distortionK1>0.478024</distortionK1>
        <distortionK2>-5.00469</distortionK2>
        <distortionK3>8.73712</distortionK3>
        <distortionT1>2.15213e-15</distortionT1>
        <distortionT2>-2.30369e-16</distortionT2>
        <CxPrime>0</CxPrime>
        <Cx>112.654</Cx>
        <Cy>87.9818</Cy>
        <focalLength>186.400175</focalLength>
        <hackBaseline>0</hackBaseline>
      </plugin>
    </sensor>
  </gazebo>
  <!--====================== Plugin TOF camera 1 ======================-->
  <!-- <gazebo reference="tof_camera_1">
      <sensor name="tof_camera_1_camera" type="depth">
        <update_rate>45</update_rate>
        <camera>
          <horizontal_fov>1.0821</horizontal_fov>
          <image>
            <width>224</width>
            <height>171</height>
            <format>L8</format>
          </image>
          <clip>
            <near>0.01</near>
            <far>4</far>
          </clip>
        </camera>
        <plugin name="camera_1_plugin" filename="libgazebo_ros_openni_kinect.so">
              <baseline>0.2</baseline>
              <alwaysOn>true</alwaysOn>
              <updateRate>0.0</updateRate>
              <cameraName>pico_flexx1</cameraName>
              <imageTopicName>/pico_flexx1/color/image_raw</imageTopicName>
              <cameraInfoTopicName>/pico_flexx1/camera_info</cameraInfoTopicName>
              <depthImageTopicName>/pico_flexx1/image_depth</depthImageTopicName>
              <depthImageCameraInfoTopicName>/pico_flexx1/camera_info</depthImageCameraInfoTopicName>
              <pointCloudTopicName>/pico_flexx1/points</pointCloudTopicName>
              <frameName>tof_camera_1</frameName>
              <pointCloudCutoff>0.5</pointCloudCutoff>
              <pointCloudCutoffMax>3.0</pointCloudCutoffMax>
              <distortionK1>0.478024</distortionK1>
              <distortionK2>-5.00469</distortionK2>
              <distortionK3>8.73712</distortionK3>
              <distortionT1>2.15213e-15</distortionT1>
              <distortionT2>-2.30369e-16</distortionT2>
              <CxPrime>0</CxPrime>
              <Cx>112.654</Cx>
              <Cy>87.9818</Cy>
              <focalLength>211.101</focalLength>
              <hackBaseline>0</hackBaseline>
        </plugin>
      </sensor>
    </gazebo> -->
  <!--====================== Plugin IMU 1 ======================-->
  <gazebo reference="imu_1">
    <sensor name="imu_sensor_1" type="imu">
      <always_on>true</always_on>
      <update_rate>100</update_rate>
      <plugin filename="libgazebo_ros_imu_sensor.so" name="imu_plugin_1">
        <topicName>imu1</topicName>
        <bodyName>imu_1</bodyName>
        <updateRateHZ>10.0</updateRateHZ>
        <gaussianNoise>0.0</gaussianNoise>
        <xyzOffset>0 0 0</xyzOffset>
        <rpyOffset>0 0 0</rpyOffset>
        <frameName>imu_1</frameName>
      </plugin>
    </sensor>
  </gazebo>
  <!--====================== Plugin IMU 2 ======================-->
  <gazebo reference="imu_2">
    <sensor name="imu_sensor_2" type="imu">
      <always_on>true</always_on>
      <update_rate>100</update_rate>
      <plugin filename="libgazebo_ros_imu_sensor.so" name="imu_plugin_2">
        <topicName>imu2</topicName>
        <bodyName>imu_2</bodyName>
        <updateRateHZ>10.0</updateRateHZ>
        <gaussianNoise>0.0</gaussianNoise>
        <xyzOffset>0 0 0</xyzOffset>
        <rpyOffset>0 0 0</rpyOffset>
        <frameName>imu_2</frameName>
      </plugin>
    </sensor>
  </gazebo>
  <gazebo>
    <plugin filename="libgazebo_ros_control.so" name="gazebo_ros_control">
      <robotNamespace>/strirus_robot</robotNamespace>
      <robotSimType>gazebo_ros_control/DefaultRobotHWSim</robotSimType>
    </plugin>
  </gazebo>
  <!-- Joint state publisher can be used either here, or in controller.yaml+roslaunch node args -->
  <gazebo>
    <plugin filename="libgazebo_ros_joint_state_publisher.so" name="joint_state_publisher">
      <robotNamespace>/strirus_robot</robotNamespace>
      <jointName>leg_left_5_revolute_joint, leg_left_4_revolute_joint, leg_left_3_revolute_joint,
                leg_left_2_revolute_joint, leg_left_1_revolute_joint, leg_left_0_revolute_joint,
                leg_right_5_revolute_joint, leg_right_4_revolute_joint, leg_right_3_revolute_joint,
                leg_right_2_revolute_joint, leg_right_1_revolute_joint, leg_right_0_revolute_joint, segment_up_revolute,
                segment_side_revolute
            </jointName>
      <updateRate>60.0</updateRate>
      <alwaysOn>true</alwaysOn>
    </plugin>
  </gazebo>
</robot>
